Workbook

Sheet Sheet1
O1: Item Scale | P1: 1.5
A3: Small | B3: y | C3: 0.17 | D3: 1 | E3: 8 | F3: 5 | G3: 4 | H3: 3 | I3: 16 | J3: 16 | K3: 19.5 | L3: 21 | M3: 32 | P3: 1 | Q3: 8 | R3: 5 | S3: 4 | T3: 3 | U3: 16 | V3: 16 | W3: 19.5 | X3: 21 | Y3: 32
D4: 1 | E4: 7 | F4: 4 | G4: 3 | H4: 2 | I4: 10 | J4: 9 | K4: 9 | L4: 9 | M4: 9 | P4: 1 | Q4: 7 | R4: 4 | S4: 3 | T4: 2 | U4: 10 | V4: 9 | W4: 9 | X4: 9 | Y4: 9
C5: x | D5: 720 | E5: =E6*E3/E4 -> 822.85714 | F5: 900 | G5: 960 | H5: 1080 | I5: 1152 | J5: 1280 | K5: 1560 | L5: 1680 | M5: =M6*M3/M4 -> 2560 | P5: ="<itemSizeSysCarousel>"&D9&" "&D8&"</itemSizeSysCarousel>" -> <itemSizeSysCarousel>0.17 0.17</itemSizeSysCarousel> | Q5: ="<itemSizeSysCarousel>"&E9&" "&E8&"</itemSizeSysCarousel>" -> <itemSizeSysCarousel>0.14875 0.17</itemSizeSysCarousel> | R5: ="<itemSizeSysCarousel>"&F9&" "&F8&"</itemSizeSysCarousel>" -> <itemSizeSysCarousel>0.136 0.17</itemSizeSysCarousel> | S5: ="<itemSizeSysCarousel>"&G9&" "&G8&"</itemSizeSysCarousel>" -> <itemSizeSysCarousel>0.1275 0.17</itemSizeSysCarousel> | T5: ="<itemSizeSysCarousel>"&H9&" "&H8&"</itemSizeSysCarousel>" -> <itemSizeSysCarousel>0.113333333333333 0.17</itemSizeSysCarousel> | U5: ="<itemSizeSysCarousel>"&I9&" "&I8&"</itemSizeSysCarousel>" -> <itemSizeSysCarousel>0.10625 0.17</itemSizeSysCarousel> | V5: ="<itemSizeSysCarousel>"&J9&" "&J8&"</itemSizeSysCarousel>" -> <itemSizeSysCarousel>0.095625 0.17</itemSizeSysCarousel> | W5: ="<itemSizeSysCarousel>"&K9&" "&K8&"</itemSizeSysCarousel>" -> <itemSizeSysCarousel>0.0784615384615385 0.17</itemSizeSysCarousel> | ... Y5: ="<itemSizeSysCarousel>"&M9&" "&M8&"</itemSizeSysCarousel>" -> <itemSizeSysCarousel>0.0478125 0.17</itemSizeSysCarousel>
C6: y | D6: 720 | E6: 720 | F6: 720 | G6: 720 | H6: 720 | I6: 720 | J6: 720 | K6: 720 | L6: 720 | M6: 720 | P6: ="<selectedItemMarginsSysCarousel>"&D12&" "&D12&"</selectedItemMarginsSysCarousel>" -> <selectedItemMarginsSysCarousel>0.0425 0.0425</selectedItemMarginsSysCarousel> | Q6: ="<selectedItemMarginsSysCarousel>"&E12&" "&E12&"</selectedItemMarginsSysCarousel>" -> <selectedItemMarginsSysCarousel>0.0371875 0.0371875</selectedItemMarginsSysCarousel> | R6: ="<selectedItemMarginsSysCarousel>"&F12&" "&F12&"</selectedItemMarginsSysCarousel>" -> <selectedItemMarginsSysCarousel>0.034 0.034</selectedItemMarginsSysCarousel> | S6: ="<selectedItemMarginsSysCarousel>"&G12&" "&G12&"</selectedItemMarginsSysCarousel>" -> <selectedItemMarginsSysCarousel>0.031875 0.031875</selectedItemMarginsSysCarousel> | T6: ="<selectedItemMarginsSysCarousel>"&H12&" "&H12&"</selectedItemMarginsSysCarousel>" -> <selectedItemMarginsSysCarousel>0.0283333333333333 0.0283333333333333</selectedItemMarginsSysCarousel> | U6: ="<selectedItemMarginsSysCarousel>"&I12&" "&I12&"</selectedItemMarginsSysCarousel>" -> <selectedItemMarginsSysCarousel>0.0265625 0.0265625</selectedItemMarginsSysCarousel> | V6: ="<selectedItemMarginsSysCarousel>"&J12&" "&J12&"</selectedItemMarginsSysCarousel>" -> <selectedItemMarginsSysCarousel>0.02390625 0.02390625</selectedItemMarginsSysCarousel> | W6: ="<selectedItemMarginsSysCarousel>"&K12&" "&K12&"</selectedItemMarginsSysCarousel>" -> <selectedItemMarginsSysCarousel>0.0196153846153846 0.0196153846153846</selectedItemMarginsSysCarousel> | ... Y6: ="<selectedItemMarginsSysCarousel>"&M12&" "&M12&"</selectedItemMarginsSysCarousel>" -> <selectedItemMarginsSysCarousel>0.011953125 0.011953125</selectedItemMarginsSysCarousel>
P7: ="<maxItemCountSysCarousel>"&D11&"</maxItemCountSysCarousel>" -> <maxItemCountSysCarousel>5.58235294117647</maxItemCountSysCarousel> | Q7: ="<maxItemCountSysCarousel>"&E11&"</maxItemCountSysCarousel>" -> <maxItemCountSysCarousel>6.37983193277311</maxItemCountSysCarousel> | R7: ="<maxItemCountSysCarousel>"&F11&"</maxItemCountSysCarousel>" -> <maxItemCountSysCarousel>6.97794117647059</maxItemCountSysCarousel> | S7: ="<maxItemCountSysCarousel>"&G11&"</maxItemCountSysCarousel>" -> <maxItemCountSysCarousel>7.44313725490196</maxItemCountSysCarousel> | T7: ="<maxItemCountSysCarousel>"&H11&"</maxItemCountSysCarousel>" -> <maxItemCountSysCarousel>8.37352941176471</maxItemCountSysCarousel> | U7: ="<maxItemCountSysCarousel>"&I11&"</maxItemCountSysCarousel>" -> <maxItemCountSysCarousel>8.93176470588235</maxItemCountSysCarousel> | V7: ="<maxItemCountSysCarousel>"&J11&"</maxItemCountSysCarousel>" -> <maxItemCountSysCarousel>9.92418300653595</maxItemCountSysCarousel> | W7: ="<maxItemCountSysCarousel>"&K11&"</maxItemCountSysCarousel>" -> <maxItemCountSysCarousel>12.0950980392157</maxItemCountSysCarousel> | ... Y7: ="<maxItemCountSysCarousel>"&M11&"</maxItemCountSysCarousel>" -> <maxItemCountSysCarousel>19.8483660130719</maxItemCountSysCarousel>
C8: Y size | D8: =$C$3 -> 0.17 | E8: =$C$3 -> 0.17 | F8: =$C$3 -> 0.17 | G8: =$C$3 -> 0.17 | H8: =$C$3 -> 0.17 | I8: =$C$3 -> 0.17 | J8: =$C$3 -> 0.17 | K8: =$C$3 -> 0.17 | ... M8: =$C$3 -> 0.17 | P8: ="<selectorXSizeSysCarousel>"&D13&"</selectorXSizeSysCarousel>" -> <selectorXSizeSysCarousel>0.257</selectorXSizeSysCarousel> | Q8: ="<selectorXSizeSysCarousel>"&E13&"</selectorXSizeSysCarousel>" -> <selectorXSizeSysCarousel>0.2252</selectorXSizeSysCarousel> | R8: ="<selectorXSizeSysCarousel>"&F13&"</selectorXSizeSysCarousel>" -> <selectorXSizeSysCarousel>0.206</selectorXSizeSysCarousel> | S8: ="<selectorXSizeSysCarousel>"&G13&"</selectorXSizeSysCarousel>" -> <selectorXSizeSysCarousel>0.1933</selectorXSizeSysCarousel> | T8: ="<selectorXSizeSysCarousel>"&H13&"</selectorXSizeSysCarousel>" -> <selectorXSizeSysCarousel>0.172</selectorXSizeSysCarousel> | U8: ="<selectorXSizeSysCarousel>"&I13&"</selectorXSizeSysCarousel>" -> <selectorXSizeSysCarousel>0.1614</selectorXSizeSysCarousel> | V8: ="<selectorXSizeSysCarousel>"&J13&"</selectorXSizeSysCarousel>" -> <selectorXSizeSysCarousel>0.1455</selectorXSizeSysCarousel> | W8: ="<selectorXSizeSysCarousel>"&K13&"</selectorXSizeSysCarousel>" -> <selectorXSizeSysCarousel>0.1197</selectorXSizeSysCarousel> | ... Y8: ="<selectorXSizeSysCarousel>"&M13&"</selectorXSizeSysCarousel>" -> <selectorXSizeSysCarousel>0.0738</selectorXSizeSysCarousel>
C9: X Size | D9: =D8*D6/D5 -> 0.17 | E9: =E8*E6/E5 -> 0.14875 | F9: =F8*F6/F5 -> 0.136 | G9: =G8*G6/G5 -> 0.1275 | H9: =H8*H6/H5 -> 0.11333333 | I9: =I8*I6/I5 -> 0.10625 | J9: =J8*J6/J5 -> 0.095625 | K9: =K8*K6/K5 -> 0.078461538 | ... M9: =M8*M6/M5 -> 0.0478125 | P9: ="<sysNameXPos>"&D17&"</sysNameXPos>" -> <sysNameXPos>0.388629653401797</sysNameXPos> | Q9: ="<sysNameXPos>"&E17&"</sysNameXPos>" -> <sysNameXPos>0.37104235004686</sysNameXPos> | R9: ="<sysNameXPos>"&F17&"</sysNameXPos>" -> <sysNameXPos>0.360531365313653</sysNameXPos> | S9: ="<sysNameXPos>"&G17&"</sysNameXPos>" -> <sysNameXPos>0.353540398660986</sysNameXPos> | T9: ="<sysNameXPos>"&H17&"</sysNameXPos>" -> <sysNameXPos>0.341916633426406</sysNameXPos> | U9: ="<sysNameXPos>"&I17&"</sysNameXPos>" -> <sysNameXPos>0.336117342776624</sysNameXPos> | V9: ="<sysNameXPos>"&J17&"</sysNameXPos>" -> <sysNameXPos>0.327433558847224</sysNameXPos> | W9: ="<sysNameXPos>"&K17&"</sysNameXPos>" -> <sysNameXPos>0.313442778393295</sysNameXPos> | ... Y9: ="<sysNameXPos>"&M17&"</sysNameXPos>" -> <sysNameXPos>0.288565179840835</sysNameXPos>
C10: Max # | D10: =1/D9 -> 5.8823529 | E10: =1/E9 -> 6.7226891 | F10: =1/F9 -> 7.3529412 | G10: =1/G9 -> 7.8431373 | H10: =1/H9 -> 8.8235294 | I10: =1/I9 -> 9.4117647 | J10: =1/J9 -> 10.457516 | K10: =1/K9 -> 12.745098 | ... M10: =1/M9 -> 20.915033
C11: Rounddown | D11: =D10-D$54 -> 5.5823529 | E11: =E10-E$54 -> 6.3798319 | F11: =F10-F$54 -> 6.9779412 | G11: =G10-G$54 -> 7.4431373 | H11: =H10-H$54 -> 8.3735294 | I11: =I10-I$54 -> 8.9317647 | J11: =J10-J$54 -> 9.924183 | K11: =K10-K$54 -> 12.095098 | ... M11: =M10-M$54 -> 19.848366
C12: selectedMargins | D12: =(($P$1*D9)-D9)/2 -> 0.0425 | E12: =(($P$1*E9)-E9)/2 -> 0.0371875 | F12: =(($P$1*F9)-F9)/2 -> 0.034 | G12: =(($P$1*G9)-G9)/2 -> 0.031875 | H12: =(($P$1*H9)-H9)/2 -> 0.028333333 | I12: =(($P$1*I9)-I9)/2 -> 0.0265625 | J12: =(($P$1*J9)-J9)/2 -> 0.02390625 | K12: =(($P$1*K9)-K9)/2 -> 0.019615385 | ... M12: =(($P$1*M9)-M9)/2 -> 0.011953125
C13: selectorX | D13: =ROUNDUP(D9*$P$1,4)+0.002 -> 0.257 | E13: =ROUNDUP(E9*$P$1,4)+0.002 -> 0.2252 | F13: =ROUNDUP(F9*$P$1,4)+0.002 -> 0.206 | G13: =ROUNDUP(G9*$P$1,4)+0.002 -> 0.1933 | H13: =ROUNDUP(H9*$P$1,4)+0.002 -> 0.172 | I13: =ROUNDUP(I9*$P$1,4)+0.002 -> 0.1614 | J13: =ROUNDUP(J9*$P$1,4)+0.002 -> 0.1455 | K13: =ROUNDUP(K9*$P$1,4)+0.002 -> 0.1197 | ... M13: =ROUNDUP(M9*$P$1,4)+0.002 -> 0.0738
C14: startYpos | D14: =0.125+(D8*$P$1) -> 0.38 | E14: =0.125+(E8*$P$1) -> 0.38 | F14: =0.125+(F8*$P$1) -> 0.38 | G14: =0.125+(G8*$P$1) -> 0.38 | H14: =0.125+(H8*$P$1) -> 0.38 | I14: =0.125+(I8*$P$1) -> 0.38 | J14: =0.125+(J8*$P$1) -> 0.38 | K14: =0.125+(K8*$P$1) -> 0.38 | ... M14: =0.125+(M8*$P$1) -> 0.38
C15: selectorYSizePS4 | D15: =(D8*$P$1)+0.049 -> 0.304 | E15: =(E8*$P$1)+0.049 -> 0.304 | F15: =(F8*$P$1)+0.049 -> 0.304 | G15: =(G8*$P$1)+0.049 -> 0.304 | H15: =(H8*$P$1)+0.049 -> 0.304 | I15: =(I8*$P$1)+0.049 -> 0.304 | J15: =(J8*$P$1)+0.049 -> 0.304 | K15: =(K8*$P$1)+0.049 -> 0.304 | ... M15: =(M8*$P$1)+0.049 -> 0.304
C16: selectorYSizePS5 | D16: =(D8*$P$1) -> 0.255 | E16: =(E8*$P$1) -> 0.255 | F16: =(F8*$P$1) -> 0.255 | G16: =(G8*$P$1) -> 0.255 | H16: =(H8*$P$1) -> 0.255 | I16: =(I8*$P$1) -> 0.255 | J16: =(J8*$P$1) -> 0.255 | K16: =(K8*$P$1) -> 0.255 | ... M16: =(M8*$P$1) -> 0.255
C17: sysNameXPos | D17: =0.25+(0.5*D9)+(D12)+(1-(D11*D9))/(D11-1) -> 0.38862965 | E17: =0.25+(0.5*E9)+(E12)+(1-(E11*E9))/(E11-1) -> 0.37104235 | F17: =0.25+(0.5*F9)+(F12)+(1-(F11*F9))/(F11-1) -> 0.36053137 | G17: =0.25+(0.5*G9)+(G12)+(1-(G11*G9))/(G11-1) -> 0.3535404 | H17: =0.25+(0.5*H9)+(H12)+(1-(H11*H9))/(H11-1) -> 0.34191663 | I17: =0.25+(0.5*I9)+(I12)+(1-(I11*I9))/(I11-1) -> 0.33611734 | J17: =0.25+(0.5*J9)+(J12)+(1-(J11*J9))/(J11-1) -> 0.32743356 | K17: =0.25+(0.5*K9)+(K12)+(1-(K11*K9))/(K11-1) -> 0.31344278 | ... M17: =0.25+(0.5*M9)+(M12)+(1-(M11*M9))/(M11-1) -> 0.28856518
A19: Medium | B19: y | C19: 0.19 | D19: 1 | E19: 8 | F19: 5 | G19: 4 | H19: 3 | I19: 16 | J19: 16 | K19: 19.5 | L19: 21 | M19: 32 | P19: 1 | Q19: 8 | R19: 5 | S19: 4 | T19: 3 | U19: 16 | V19: 16 | W19: 19.5 | X19: 21 | Y19: 32
D20: 1 | E20: 7 | F20: 4 | G20: 3 | H20: 2 | I20: 10 | J20: 9 | K20: 9 | L20: 9 | M20: 9 | P20: 1 | Q20: 7 | R20: 4 | S20: 3 | T20: 2 | U20: 10 | V20: 9 | W20: 9 | X20: 9 | Y20: 9
C21: x | D21: 720 | E21: =E22*E19/E20 -> 822.85714 | F21: 900 | G21: 960 | H21: 1080 | I21: 1152 | J21: 1280 | K21: 1560 | L21: 1680 | M21: =M22*M19/M20 -> 2560 | P21: ="<itemSizeSysCarousel>"&D25&" "&D24&"</itemSizeSysCarousel>" -> <itemSizeSysCarousel>0.19 0.19</itemSizeSysCarousel> | Q21: ="<itemSizeSysCarousel>"&E25&" "&E24&"</itemSizeSysCarousel>" -> <itemSizeSysCarousel>0.16625 0.19</itemSizeSysCarousel> | R21: ="<itemSizeSysCarousel>"&F25&" "&F24&"</itemSizeSysCarousel>" -> <itemSizeSysCarousel>0.152 0.19</itemSizeSysCarousel> | S21: ="<itemSizeSysCarousel>"&G25&" "&G24&"</itemSizeSysCarousel>" -> <itemSizeSysCarousel>0.1425 0.19</itemSizeSysCarousel> | T21: ="<itemSizeSysCarousel>"&H25&" "&H24&"</itemSizeSysCarousel>" -> <itemSizeSysCarousel>0.126666666666667 0.19</itemSizeSysCarousel> | U21: ="<itemSizeSysCarousel>"&I25&" "&I24&"</itemSizeSysCarousel>" -> <itemSizeSysCarousel>0.11875 0.19</itemSizeSysCarousel> | V21: ="<itemSizeSysCarousel>"&J25&" "&J24&"</itemSizeSysCarousel>" -> <itemSizeSysCarousel>0.106875 0.19</itemSizeSysCarousel> | W21: ="<itemSizeSysCarousel>"&K25&" "&K24&"</itemSizeSysCarousel>" -> <itemSizeSysCarousel>0.0876923076923077 0.19</itemSizeSysCarousel> | ... Y21: ="<itemSizeSysCarousel>"&M25&" "&M24&"</itemSizeSysCarousel>" -> <itemSizeSysCarousel>0.0534375 0.19</itemSizeSysCarousel>
C22: y | D22: 720 | E22: 720 | F22: 720 | G22: 720 | H22: 720 | I22: 720 | J22: 720 | K22: 720 | L22: 720 | M22: 720 | P22: ="<selectedItemMarginsSysCarousel>"&D28&" "&D28&"</selectedItemMarginsSysCarousel>" -> <selectedItemMarginsSysCarousel>0.0475 0.0475</selectedItemMarginsSysCarousel> | Q22: ="<selectedItemMarginsSysCarousel>"&E28&" "&E28&"</selectedItemMarginsSysCarousel>" -> <selectedItemMarginsSysCarousel>0.0415625 0.0415625</selectedItemMarginsSysCarousel> | R22: ="<selectedItemMarginsSysCarousel>"&F28&" "&F28&"</selectedItemMarginsSysCarousel>" -> <selectedItemMarginsSysCarousel>0.038 0.038</selectedItemMarginsSysCarousel> | S22: ="<selectedItemMarginsSysCarousel>"&G28&" "&G28&"</selectedItemMarginsSysCarousel>" -> <selectedItemMarginsSysCarousel>0.035625 0.035625</selectedItemMarginsSysCarousel> | T22: ="<selectedItemMarginsSysCarousel>"&H28&" "&H28&"</selectedItemMarginsSysCarousel>" -> <selectedItemMarginsSysCarousel>0.0316666666666667 0.0316666666666667</selectedItemMarginsSysCarousel> | U22: ="<selectedItemMarginsSysCarousel>"&I28&" "&I28&"</selectedItemMarginsSysCarousel>" -> <selectedItemMarginsSysCarousel>0.0296875 0.0296875</selectedItemMarginsSysCarousel> | V22: ="<selectedItemMarginsSysCarousel>"&J28&" "&J28&"</selectedItemMarginsSysCarousel>" -> <selectedItemMarginsSysCarousel>0.02671875 0.02671875</selectedItemMarginsSysCarousel> | W22: ="<selectedItemMarginsSysCarousel>"&K28&" "&K28&"</selectedItemMarginsSysCarousel>" -> <selectedItemMarginsSysCarousel>0.0219230769230769 0.0219230769230769</selectedItemMarginsSysCarousel> | ... Y22: ="<selectedItemMarginsSysCarousel>"&M28&" "&M28&"</selectedItemMarginsSysCarousel>" -> <selectedItemMarginsSysCarousel>0.013359375 0.013359375</selectedItemMarginsSysCarousel>
P23: ="<maxItemCountSysCarousel>"&D27&"</maxItemCountSysCarousel>" -> <maxItemCountSysCarousel>4.96315789473684</maxItemCountSysCarousel> | Q23: ="<maxItemCountSysCarousel>"&E27&"</maxItemCountSysCarousel>" -> <maxItemCountSysCarousel>5.67218045112782</maxItemCountSysCarousel> | R23: ="<maxItemCountSysCarousel>"&F27&"</maxItemCountSysCarousel>" -> <maxItemCountSysCarousel>6.20394736842105</maxItemCountSysCarousel> | S23: ="<maxItemCountSysCarousel>"&G27&"</maxItemCountSysCarousel>" -> <maxItemCountSysCarousel>6.61754385964912</maxItemCountSysCarousel> | T23: ="<maxItemCountSysCarousel>"&H27&"</maxItemCountSysCarousel>" -> <maxItemCountSysCarousel>7.44473684210526</maxItemCountSysCarousel> | U23: ="<maxItemCountSysCarousel>"&I27&"</maxItemCountSysCarousel>" -> <maxItemCountSysCarousel>7.94105263157895</maxItemCountSysCarousel> | V23: ="<maxItemCountSysCarousel>"&J27&"</maxItemCountSysCarousel>" -> <maxItemCountSysCarousel>8.8233918128655</maxItemCountSysCarousel> | W23: ="<maxItemCountSysCarousel>"&K27&"</maxItemCountSysCarousel>" -> <maxItemCountSysCarousel>10.7535087719298</maxItemCountSysCarousel> | ... Y23: ="<maxItemCountSysCarousel>"&M27&"</maxItemCountSysCarousel>" -> <maxItemCountSysCarousel>17.646783625731</maxItemCountSysCarousel>
C24: Y size | D24: =$C$19 -> 0.19 | E24: =$C$19 -> 0.19 | F24: =$C$19 -> 0.19 | G24: =$C$19 -> 0.19 | H24: =$C$19 -> 0.19 | I24: =$C$19 -> 0.19 | J24: =$C$19 -> 0.19 | K24: =$C$19 -> 0.19 | ... M24: =$C$19 -> 0.19 | P24: ="<selectorXSizeSysCarousel>"&D29&"</selectorXSizeSysCarousel>" -> <selectorXSizeSysCarousel>0.287</selectorXSizeSysCarousel> | Q24: ="<selectorXSizeSysCarousel>"&E29&"</selectorXSizeSysCarousel>" -> <selectorXSizeSysCarousel>0.2514</selectorXSizeSysCarousel> | R24: ="<selectorXSizeSysCarousel>"&F29&"</selectorXSizeSysCarousel>" -> <selectorXSizeSysCarousel>0.23</selectorXSizeSysCarousel> | S24: ="<selectorXSizeSysCarousel>"&G29&"</selectorXSizeSysCarousel>" -> <selectorXSizeSysCarousel>0.2158</selectorXSizeSysCarousel> | T24: ="<selectorXSizeSysCarousel>"&H29&"</selectorXSizeSysCarousel>" -> <selectorXSizeSysCarousel>0.192</selectorXSizeSysCarousel> | U24: ="<selectorXSizeSysCarousel>"&I29&"</selectorXSizeSysCarousel>" -> <selectorXSizeSysCarousel>0.1802</selectorXSizeSysCarousel> | V24: ="<selectorXSizeSysCarousel>"&J29&"</selectorXSizeSysCarousel>" -> <selectorXSizeSysCarousel>0.1624</selectorXSizeSysCarousel> | W24: ="<selectorXSizeSysCarousel>"&K29&"</selectorXSizeSysCarousel>" -> <selectorXSizeSysCarousel>0.1336</selectorXSizeSysCarousel> | ... Y24: ="<selectorXSizeSysCarousel>"&M29&"</selectorXSizeSysCarousel>" -> <selectorXSizeSysCarousel>0.0822</selectorXSizeSysCarousel>
C25: X Size | D25: =D24*D22/D21 -> 0.19 | E25: =E24*E22/E21 -> 0.16625 | F25: =F24*F22/F21 -> 0.152 | G25: =G24*G22/G21 -> 0.1425 | H25: =H24*H22/H21 -> 0.12666667 | I25: =I24*I22/I21 -> 0.11875 | J25: =J24*J22/J21 -> 0.106875 | K25: =K24*K22/K21 -> 0.087692308 | ... M25: =M24*M22/M21 -> 0.0534375 | P25: ="<sysNameXPos>"&D33&"</sysNameXPos>" -> <sysNameXPos>0.406882470119522</sysNameXPos> | Q25: ="<sysNameXPos>"&E33&"</sysNameXPos>" -> <sysNameXPos>0.386887371258449</sysNameXPos> | R25: ="<sysNameXPos>"&F33&"</sysNameXPos>" -> <sysNameXPos>0.374953223767383</sysNameXPos> | S25: ="<sysNameXPos>"&G33&"</sysNameXPos>" -> <sysNameXPos>0.367021783260462</sysNameXPos> | T25: ="<sysNameXPos>"&H33&"</sysNameXPos>" -> <sysNameXPos>0.353844426296448</sysNameXPos> | U25: ="<sysNameXPos>"&I33&"</sysNameXPos>" -> <sysNameXPos>0.347274510919017</sysNameXPos> | V25: ="<sysNameXPos>"&J33&"</sysNameXPos>" -> <sysNameXPos>0.337442092427867</sysNameXPos> | W25: ="<sysNameXPos>"&K33&"</sysNameXPos>" -> <sysNameXPos>0.321613281493217</sysNameXPos> | ... Y25: ="<sysNameXPos>"&M33&"</sysNameXPos>" -> <sysNameXPos>0.293502209873182</sysNameXPos>
C26: Max # | D26: =1/D25 -> 5.2631579 | E26: =1/E25 -> 6.0150376 | F26: =1/F25 -> 6.5789474 | G26: =1/G25 -> 7.0175439 | H26: =1/H25 -> 7.8947368 | I26: =1/I25 -> 8.4210526 | J26: =1/J25 -> 9.3567251 | K26: =1/K25 -> 11.403509 | ... M26: =1/M25 -> 18.71345
C27: Rounddown | D27: =D26-D$54 -> 4.9631579 | E27: =E26-E$54 -> 5.6721805 | F27: =F26-F$54 -> 6.2039474 | G27: =G26-G$54 -> 6.6175439 | H27: =H26-H$54 -> 7.4447368 | I27: =I26-I$54 -> 7.9410526 | J27: =J26-J$54 -> 8.8233918 | K27: =K26-K$54 -> 10.753509 | ... M27: =M26-M$54 -> 17.646784
C28: selectedMargins | D28: =(($P$1*D25)-D25)/2 -> 0.0475 | E28: =(($P$1*E25)-E25)/2 -> 0.0415625 | F28: =(($P$1*F25)-F25)/2 -> 0.038 | G28: =(($P$1*G25)-G25)/2 -> 0.035625 | H28: =(($P$1*H25)-H25)/2 -> 0.031666667 | I28: =(($P$1*I25)-I25)/2 -> 0.0296875 | J28: =(($P$1*J25)-J25)/2 -> 0.02671875 | K28: =(($P$1*K25)-K25)/2 -> 0.021923077 | ... M28: =(($P$1*M25)-M25)/2 -> 0.013359375
C29: selectorX | D29: =ROUNDUP(D25*$P$1,4)+0.002 -> 0.287 | E29: =ROUNDUP(E25*$P$1,4)+0.002 -> 0.2514 | F29: =ROUNDUP(F25*$P$1,4)+0.002 -> 0.23 | G29: =ROUNDUP(G25*$P$1,4)+0.002 -> 0.2158 | H29: =ROUNDUP(H25*$P$1,4)+0.002 -> 0.192 | I29: =ROUNDUP(I25*$P$1,4)+0.002 -> 0.1802 | J29: =ROUNDUP(J25*$P$1,4)+0.002 -> 0.1624 | K29: =ROUNDUP(K25*$P$1,4)+0.002 -> 0.1336 | ... M29: =ROUNDUP(M25*$P$1,4)+0.002 -> 0.0822
C30: startYpos | D30: =0.125+(D24*$P$1) -> 0.41 | E30: =0.125+(E24*$P$1) -> 0.41 | F30: =0.125+(F24*$P$1) -> 0.41 | G30: =0.125+(G24*$P$1) -> 0.41 | H30: =0.125+(H24*$P$1) -> 0.41 | I30: =0.125+(I24*$P$1) -> 0.41 | J30: =0.125+(J24*$P$1) -> 0.41 | K30: =0.125+(K24*$P$1) -> 0.41 | ... M30: =0.125+(M24*$P$1) -> 0.41
C31: selectorYSizePS4 | D31: =(D24*$P$1)+0.049 -> 0.334 | E31: =(E24*$P$1)+0.049 -> 0.334 | F31: =(F24*$P$1)+0.049 -> 0.334 | G31: =(G24*$P$1)+0.049 -> 0.334 | H31: =(H24*$P$1)+0.049 -> 0.334 | I31: =(I24*$P$1)+0.049 -> 0.334 | J31: =(J24*$P$1)+0.049 -> 0.334 | K31: =(K24*$P$1)+0.049 -> 0.334 | ... M31: =(M24*$P$1)+0.049 -> 0.334
C32: selectorYSizePS5 | D32: =(D24*$P$1) -> 0.285 | E32: =(E24*$P$1) -> 0.285 | F32: =(F24*$P$1) -> 0.285 | G32: =(G24*$P$1) -> 0.285 | H32: =(H24*$P$1) -> 0.285 | I32: =(I24*$P$1) -> 0.285 | J32: =(J24*$P$1) -> 0.285 | K32: =(K24*$P$1) -> 0.285 | ... M32: =(M24*$P$1) -> 0.285
C33: sysNameXPos | D33: =0.25+(0.5*D25)+(D28)+(1-(D27*D25))/(D27-1) -> 0.40688247 | E33: =0.25+(0.5*E25)+(E28)+(1-(E27*E25))/(E27-1) -> 0.38688737 | F33: =0.25+(0.5*F25)+(F28)+(1-(F27*F25))/(F27-1) -> 0.37495322 | G33: =0.25+(0.5*G25)+(G28)+(1-(G27*G25))/(G27-1) -> 0.36702178 | H33: =0.25+(0.5*H25)+(H28)+(1-(H27*H25))/(H27-1) -> 0.35384443 | I33: =0.25+(0.5*I25)+(I28)+(1-(I27*I25))/(I27-1) -> 0.34727451 | J33: =0.25+(0.5*J25)+(J28)+(1-(J27*J25))/(J27-1) -> 0.33744209 | K33: =0.25+(0.5*K25)+(K28)+(1-(K27*K25))/(K27-1) -> 0.32161328 | ... M33: =0.25+(0.5*M25)+(M28)+(1-(M27*M25))/(M27-1) -> 0.29350221
A35: Large | B35: y | C35: 0.21 | D35: 1 | E35: 8 | F35: 5 | G35: 4 | H35: 3 | I35: 16 | J35: 16 | K35: 19.5 | L35: 21 | M35: 32 | P35: 1 | Q35: 8 | R35: 5 | S35: 4 | T35: 3 | U35: 16 | V35: 16 | W35: 19.5 | X35: 21 | Y35: 32
D36: 1 | E36: 7 | F36: 4 | G36: 3 | H36: 2 | I36: 10 | J36: 9 | K36: 9 | L36: 9 | M36: 9 | P36: 1 | Q36: 7 | R36: 4 | S36: 3 | T36: 2 | U36: 10 | V36: 9 | W36: 9 | X36: 9 | Y36: 9
C37: x | D37: 720 | E37: =E38*E35/E36 -> 822.85714 | F37: 900 | G37: 960 | H37: 1080 | I37: 1152 | J37: 1280 | K37: 1560 | L37: 1680 | M37: =M38*M35/M36 -> 2560 | P37: ="<itemSizeSysCarousel>"&D41&" "&D40&"</itemSizeSysCarousel>" -> <itemSizeSysCarousel>0.21 0.21</itemSizeSysCarousel> | Q37: ="<itemSizeSysCarousel>"&E41&" "&E40&"</itemSizeSysCarousel>" -> <itemSizeSysCarousel>0.18375 0.21</itemSizeSysCarousel> | R37: ="<itemSizeSysCarousel>"&F41&" "&F40&"</itemSizeSysCarousel>" -> <itemSizeSysCarousel>0.168 0.21</itemSizeSysCarousel> | S37: ="<itemSizeSysCarousel>"&G41&" "&G40&"</itemSizeSysCarousel>" -> <itemSizeSysCarousel>0.1575 0.21</itemSizeSysCarousel> | T37: ="<itemSizeSysCarousel>"&H41&" "&H40&"</itemSizeSysCarousel>" -> <itemSizeSysCarousel>0.14 0.21</itemSizeSysCarousel> | U37: ="<itemSizeSysCarousel>"&I41&" "&I40&"</itemSizeSysCarousel>" -> <itemSizeSysCarousel>0.13125 0.21</itemSizeSysCarousel> | V37: ="<itemSizeSysCarousel>"&J41&" "&J40&"</itemSizeSysCarousel>" -> <itemSizeSysCarousel>0.118125 0.21</itemSizeSysCarousel> | W37: ="<itemSizeSysCarousel>"&K41&" "&K40&"</itemSizeSysCarousel>" -> <itemSizeSysCarousel>0.0969230769230769 0.21</itemSizeSysCarousel> | ... Y37: ="<itemSizeSysCarousel>"&M41&" "&M40&"</itemSizeSysCarousel>" -> <itemSizeSysCarousel>0.0590625 0.21</itemSizeSysCarousel>
C38: y | D38: 720 | E38: 720 | F38: 720 | G38: 720 | H38: 720 | I38: 720 | J38: 720 | K38: 720 | L38: 720 | M38: 720 | P38: ="<selectedItemMarginsSysCarousel>"&D44&" "&D44&"</selectedItemMarginsSysCarousel>" -> <selectedItemMarginsSysCarousel>0.0525 0.0525</selectedItemMarginsSysCarousel> | Q38: ="<selectedItemMarginsSysCarousel>"&E44&" "&E44&"</selectedItemMarginsSysCarousel>" -> <selectedItemMarginsSysCarousel>0.0459375 0.0459375</selectedItemMarginsSysCarousel> | R38: ="<selectedItemMarginsSysCarousel>"&F44&" "&F44&"</selectedItemMarginsSysCarousel>" -> <selectedItemMarginsSysCarousel>0.042 0.042</selectedItemMarginsSysCarousel> | S38: ="<selectedItemMarginsSysCarousel>"&G44&" "&G44&"</selectedItemMarginsSysCarousel>" -> <selectedItemMarginsSysCarousel>0.039375 0.039375</selectedItemMarginsSysCarousel> | T38: ="<selectedItemMarginsSysCarousel>"&H44&" "&H44&"</selectedItemMarginsSysCarousel>" -> <selectedItemMarginsSysCarousel>0.035 0.035</selectedItemMarginsSysCarousel> | U38: ="<selectedItemMarginsSysCarousel>"&I44&" "&I44&"</selectedItemMarginsSysCarousel>" -> <selectedItemMarginsSysCarousel>0.0328125 0.0328125</selectedItemMarginsSysCarousel> | V38: ="<selectedItemMarginsSysCarousel>"&J44&" "&J44&"</selectedItemMarginsSysCarousel>" -> <selectedItemMarginsSysCarousel>0.02953125 0.02953125</selectedItemMarginsSysCarousel> | W38: ="<selectedItemMarginsSysCarousel>"&K44&" "&K44&"</selectedItemMarginsSysCarousel>" -> <selectedItemMarginsSysCarousel>0.0242307692307692 0.0242307692307692</selectedItemMarginsSysCarousel> | ... Y38: ="<selectedItemMarginsSysCarousel>"&M44&" "&M44&"</selectedItemMarginsSysCarousel>" -> <selectedItemMarginsSysCarousel>0.014765625 0.014765625</selectedItemMarginsSysCarousel>
P39: ="<maxItemCountSysCarousel>"&D43&"</maxItemCountSysCarousel>" -> <maxItemCountSysCarousel>4.46190476190476</maxItemCountSysCarousel> | Q39: ="<maxItemCountSysCarousel>"&E43&"</maxItemCountSysCarousel>" -> <maxItemCountSysCarousel>5.09931972789116</maxItemCountSysCarousel> | R39: ="<maxItemCountSysCarousel>"&F43&"</maxItemCountSysCarousel>" -> <maxItemCountSysCarousel>5.57738095238095</maxItemCountSysCarousel> | S39: ="<maxItemCountSysCarousel>"&G43&"</maxItemCountSysCarousel>" -> <maxItemCountSysCarousel>5.94920634920635</maxItemCountSysCarousel> | T39: ="<maxItemCountSysCarousel>"&H43&"</maxItemCountSysCarousel>" -> <maxItemCountSysCarousel>6.69285714285714</maxItemCountSysCarousel> | U39: ="<maxItemCountSysCarousel>"&I43&"</maxItemCountSysCarousel>" -> <maxItemCountSysCarousel>7.13904761904762</maxItemCountSysCarousel> | V39: ="<maxItemCountSysCarousel>"&J43&"</maxItemCountSysCarousel>" -> <maxItemCountSysCarousel>7.93227513227513</maxItemCountSysCarousel> | W39: ="<maxItemCountSysCarousel>"&K43&"</maxItemCountSysCarousel>" -> <maxItemCountSysCarousel>9.66746031746032</maxItemCountSysCarousel> | ... Y39: ="<maxItemCountSysCarousel>"&M43&"</maxItemCountSysCarousel>" -> <maxItemCountSysCarousel>15.8645502645503</maxItemCountSysCarousel>
C40: Y size | D40: =$C$35 -> 0.21 | E40: =$C$35 -> 0.21 | F40: =$C$35 -> 0.21 | G40: =$C$35 -> 0.21 | H40: =$C$35 -> 0.21 | I40: =$C$35 -> 0.21 | J40: =$C$35 -> 0.21 | K40: =$C$35 -> 0.21 | ... M40: =$C$35 -> 0.21 | P40: ="<selectorXSizeSysCarousel>"&D45&"</selectorXSizeSysCarousel>" -> <selectorXSizeSysCarousel>0.317</selectorXSizeSysCarousel> | Q40: ="<selectorXSizeSysCarousel>"&E45&"</selectorXSizeSysCarousel>" -> <selectorXSizeSysCarousel>0.2777</selectorXSizeSysCarousel> | R40: ="<selectorXSizeSysCarousel>"&F45&"</selectorXSizeSysCarousel>" -> <selectorXSizeSysCarousel>0.254</selectorXSizeSysCarousel> | S40: ="<selectorXSizeSysCarousel>"&G45&"</selectorXSizeSysCarousel>" -> <selectorXSizeSysCarousel>0.2383</selectorXSizeSysCarousel> | T40: ="<selectorXSizeSysCarousel>"&H45&"</selectorXSizeSysCarousel>" -> <selectorXSizeSysCarousel>0.212</selectorXSizeSysCarousel> | U40: ="<selectorXSizeSysCarousel>"&I45&"</selectorXSizeSysCarousel>" -> <selectorXSizeSysCarousel>0.1989</selectorXSizeSysCarousel> | V40: ="<selectorXSizeSysCarousel>"&J45&"</selectorXSizeSysCarousel>" -> <selectorXSizeSysCarousel>0.1792</selectorXSizeSysCarousel> | W40: ="<selectorXSizeSysCarousel>"&K45&"</selectorXSizeSysCarousel>" -> <selectorXSizeSysCarousel>0.1474</selectorXSizeSysCarousel> | ... Y40: ="<selectorXSizeSysCarousel>"&M45&"</selectorXSizeSysCarousel>" -> <selectorXSizeSysCarousel>0.0906</selectorXSizeSysCarousel>
C41: X Size | D41: =D40*D38/D37 -> 0.21 | E41: =E40*E38/E37 -> 0.18375 | F41: =F40*F38/F37 -> 0.168 | G41: =G40*G38/G37 -> 0.1575 | H41: =H40*H38/H37 -> 0.14 | I41: =I40*I38/I37 -> 0.13125 | J41: =J40*J38/J37 -> 0.118125 | K41: =K40*K38/K37 -> 0.096923077 | ... M41: =M40*M38/M37 -> 0.0590625 | P41: ="<sysNameXPos>"&D49&"</sysNameXPos>" -> <sysNameXPos>0.425698074277854</sysNameXPos> | Q41: ="<sysNameXPos>"&E49&"</sysNameXPos>" -> <sysNameXPos>0.403180903584467</sysNameXPos> | R41: ="<sysNameXPos>"&F49&"</sysNameXPos>" -> <sysNameXPos>0.3897633289987</sysNameXPos> | S41: ="<sysNameXPos>"&G49&"</sysNameXPos>" -> <sysNameXPos>0.380854313662604</sysNameXPos> | T41: ="<sysNameXPos>"&H49&"</sysNameXPos>" -> <sysNameXPos>0.366066499372647</sysNameXPos> | U41: ="<sysNameXPos>"&I49&"</sysNameXPos>" -> <sysNameXPos>0.358699678094943</sysNameXPos> | V41: ="<sysNameXPos>"&J49&"</sysNameXPos>" -> <sysNameXPos>0.347681675507556</sysNameXPos> | W41: ="<sysNameXPos>"&K49&"</sysNameXPos>" -> <sysNameXPos>0.329960872842019</sysNameXPos> | ... Y41: ="<sysNameXPos>"&M49&"</sysNameXPos>" -> <sysNameXPos>0.29853514651705</sysNameXPos>
C42: Max # | D42: =1/D41 -> 4.7619048 | E42: =1/E41 -> 5.4421769 | F42: =1/F41 -> 5.952381 | G42: =1/G41 -> 6.3492063 | H42: =1/H41 -> 7.1428571 | I42: =1/I41 -> 7.6190476 | J42: =1/J41 -> 8.4656085 | K42: =1/K41 -> 10.31746 | ... M42: =1/M41 -> 16.931217
C43: Rounddown | D43: =D42-D$54 -> 4.4619048 | E43: =E42-E$54 -> 5.0993197 | F43: =F42-F$54 -> 5.577381 | G43: =G42-G$54 -> 5.9492063 | H43: =H42-H$54 -> 6.6928571 | I43: =I42-I$54 -> 7.1390476 | J43: =J42-J$54 -> 7.9322751 | K43: =K42-K$54 -> 9.6674603 | ... M43: =M42-M$54 -> 15.86455
...

Sheet xml
A1: <theme>
B2: <aspectRatio name="1:1">
C3: <fontSize name="small">
D4: <variables>
E5: =Sheet1!P5 -> <itemSizeSysCarousel>0.17 0.17</itemSizeSysCarousel>
E6: =Sheet1!P6 -> <selectedItemMarginsSysCarousel>0.0425 0.0425</selectedItemMarginsSysCarousel>
E7: =Sheet1!P7 -> <maxItemCountSysCarousel>5.58235294117647</maxItemCountSysCarousel>
E8: =Sheet1!P8 -> <selectorXSizeSysCarousel>0.257</selectorXSizeSysCarousel>
E9: =Sheet1!P9 -> <sysNameXPos>0.388629653401797</sysNameXPos>
D10: </variables>
C11: </fontSize>
C12: <fontSize name="medium">
D13: <variables>
E14: =Sheet1!P21 -> <itemSizeSysCarousel>0.19 0.19</itemSizeSysCarousel>
E15: =Sheet1!P22 -> <selectedItemMarginsSysCarousel>0.0475 0.0475</selectedItemMarginsSysCarousel>
E16: =Sheet1!P23 -> <maxItemCountSysCarousel>4.96315789473684</maxItemCountSysCarousel>
E17: =Sheet1!P24 -> <selectorXSizeSysCarousel>0.287</selectorXSizeSysCarousel>
E18: =Sheet1!P25 -> <sysNameXPos>0.406882470119522</sysNameXPos>
D19: </variables>
C20: </fontSize>
C21: <fontSize name="large">
D22: <variables>
E23: =Sheet1!P37 -> <itemSizeSysCarousel>0.21 0.21</itemSizeSysCarousel>
E24: =Sheet1!P38 -> <selectedItemMarginsSysCarousel>0.0525 0.0525</selectedItemMarginsSysCarousel>
E25: =Sheet1!P39 -> <maxItemCountSysCarousel>4.46190476190476</maxItemCountSysCarousel>
E26: =Sheet1!P40 -> <selectorXSizeSysCarousel>0.317</selectorXSizeSysCarousel>
E27: =Sheet1!P41 -> <sysNameXPos>0.425698074277854</sysNameXPos>
D28: </variables>
C29: </fontSize>
B30: </aspectRatio>
B31: <aspectRatio name="8:7">
C32: <fontSize name="small">
D33: <variables>
E34: =Sheet1!Q5 -> <itemSizeSysCarousel>0.14875 0.17</itemSizeSysCarousel>
E35: =Sheet1!Q6 -> <selectedItemMarginsSysCarousel>0.0371875 0.0371875</selectedItemMarginsSysCarousel>
E36: =Sheet1!Q7 -> <maxItemCountSysCarousel>6.37983193277311</maxItemCountSysCarousel>
E37: =Sheet1!Q8 -> <selectorXSizeSysCarousel>0.2252</selectorXSizeSysCarousel>
E38: =Sheet1!Q9 -> <sysNameXPos>0.37104235004686</sysNameXPos>
D39: </variables>
C40: </fontSize>
...
